Workbook

Sheet Sheet1
A1: Ada | B1: Rifqi Abdillah | C1: 000 | D1: accepted | E1: Comparative Study of Rice Disease Detection Using ConvNeXt-Base and Conventional CNN Models | F1: Samuel Welson, S.Kom; Aniek Suryanti Kusuma; Putu Sugiartawan | G1: 46247 | H1: 2026 Ninth International Conference on Vocational Education and Electrical Engineering (ICVEE) | I1: 17-18 September 2026 | J1: Surabaya, Indonesia | K1: Prof. Dr. Nurhayati, S.T., M.T. | L1: General Chair
A2: =IF(COUNTIF(Sheet2!A:A,C2)>0,"Ada","Tidak Ada") -> Tidak Ada | B2: =IF(A2="Ada",IF(IFERROR(VLOOKUP(C2,Sheet2!A:C,2,FALSE),"")="",IFERROR(VLOOKUP(C2,Sheet2!A:C,3,FALSE),""),VLOOKUP(C2,Sheet2!A:C,2,FALSE)),"") | C2: 1571257569 | D2: accepted | E2: Comparative Study of Rice Disease Detection Using ConvNeXt-Base and Conventional CNN Models | F2: Samuel Welson, S.Kom; Aniek Suryanti Kusuma; Putu Sugiartawan | G2: 46247 | H2: 2026 Ninth International Conference on Vocational Education and Electrical Engineering (ICVEE) | I2: 17-18 September 2026 | J2: Surabaya, Indonesia | K2: Prof. Dr. Nurhayati, S.T., M.T. | L2: General Chair
A3: =IF(COUNTIF(Sheet2!A:A,C3)>0,"Ada","Tidak Ada") -> Ada | B3: =IF(A3="Ada",IF(IFERROR(VLOOKUP(C3,Sheet2!A:C,2,FALSE),"")="",IFERROR(VLOOKUP(C3,Sheet2!A:C,3,FALSE),""),VLOOKUP(C3,Sheet2!A:C,2,FALSE)),"") -> Dr. I Nyoman Kusuma Wardana | C3: 1571267469 | D3: accepted | E3: SentinelGuard-AI: Multi-Type Attack Detection Framework Using Natural Language Processing Processing (NLP) and Deep Q-Networks Reinforcement Learning (DQN-RL) | F3: Carlo Jude P Abuda; Kent Claire Apple Joy M Pallomina; Ketan Raju Kundiya; Cristina Dumdumaya | G3: 46247 | H3: 2026 Ninth International Conference on Vocational Education and Electrical Engineering (ICVEE) | I3: 17-18 September 2026 | J3: Surabaya, Indonesia | K3: Prof. Dr. Nurhayati, S.T., M.T. | L3: General Chair
A4: =IF(COUNTIF(Sheet2!A:A,C4)>0,"Ada","Tidak Ada") -> Ada | B4: =IF(A4="Ada",IF(IFERROR(VLOOKUP(C4,Sheet2!A:C,2,FALSE),"")="",IFERROR(VLOOKUP(C4,Sheet2!A:C,3,FALSE),""),VLOOKUP(C4,Sheet2!A:C,2,FALSE)),"") -> Athif Fadheel Atharahman | C4: 1571267484 | D4: accepted | E4: Admission-to-Enrollment Outcome Forecasting Through Predictive Modeling for Visayas State University Alangalang | F4: Carlo Jude P Abuda; Kent Claire Apple Joy M Pallomina; Ronnie L. Luriaga; Maureen M Villamor | G4: 46247 | H4: 2026 Ninth International Conference on Vocational Education and Electrical Engineering (ICVEE) | I4: 17-18 September 2026 | J4: Surabaya, Indonesia | K4: Prof. Dr. Nurhayati, S.T., M.T. | L4: General Chair
A5: =IF(COUNTIF(Sheet2!A:A,C5)>0,"Ada","Tidak Ada") -> Ada | B5: =IF(A5="Ada",IF(IFERROR(VLOOKUP(C5,Sheet2!A:C,2,FALSE),"")="",IFERROR(VLOOKUP(C5,Sheet2!A:C,3,FALSE),""),VLOOKUP(C5,Sheet2!A:C,2,FALSE)),"") -> Muhammad Andika Fadilla, S.Kom | C5: 1571267967 | D5: accepted | E5: The Efficacy of Large Language Model Tools in Solving Electrical Circuit Problems | F5: Mohamad Ramdhani; Athif Fadheel Atharahman; Suksmandhira Harimurti; Diyah Widiyasari | G5: 46247 | H5: 2026 Ninth International Conference on Vocational Education and Electrical Engineering (ICVEE) | I5: 17-18 September 2026 | J5: Surabaya, Indonesia | K5: Prof. Dr. Nurhayati, S.T., M.T. | L5: General Chair
A6: =IF(COUNTIF(Sheet2!A:A,C6)>0,"Ada","Tidak Ada") -> Ada | B6: =IF(A6="Ada",IF(IFERROR(VLOOKUP(C6,Sheet2!A:C,2,FALSE),"")="",IFERROR(VLOOKUP(C6,Sheet2!A:C,3,FALSE),""),VLOOKUP(C6,Sheet2!A:C,2,FALSE)),"") -> Muhammad Raya Maulana, S.T | C6: 1571268176 | D6: accepted | E6: Syntax-Preserving Diffusion Modeling of SQL Injection Attack Payloads Using Hilbert Space Feature Mapping | F6: Carlo Jude P Abuda; Kent Claire Apple Joy M Pallomina; Ketan Raju Kundiya | G6: 46247 | H6: 2026 Ninth International Conference on Vocational Education and Electrical Engineering (ICVEE) | I6: 17-18 September 2026 | J6: Surabaya, Indonesia | K6: Prof. Dr. Nurhayati, S.T., M.T. | L6: General Chair
A7: =IF(COUNTIF(Sheet2!A:A,C7)>0,"Ada","Tidak Ada") -> Tidak Ada | B7: =IF(A7="Ada",IF(IFERROR(VLOOKUP(C7,Sheet2!A:C,2,FALSE),"")="",IFERROR(VLOOKUP(C7,Sheet2!A:C,3,FALSE),""),VLOOKUP(C7,Sheet2!A:C,2,FALSE)),"") | C7: 1571273336 | D7: accepted | E7: An AI-Assisted QR-Based Assessment Model for Integrating Technical Mandarin and Vocational Competence in Indonesian Vocational Education | F7: S Sunarti | G7: 46247 | H7: 2026 Ninth International Conference on Vocational Education and Electrical Engineering (ICVEE) | I7: 17-18 September 2026 | J7: Surabaya, Indonesia | K7: Prof. Dr. Nurhayati, S.T., M.T. | L7: General Chair
A8: =IF(COUNTIF(Sheet2!A:A,C8)>0,"Ada","Tidak Ada") -> Ada | B8: =IF(A8="Ada",IF(IFERROR(VLOOKUP(C8,Sheet2!A:C,2,FALSE),"")="",IFERROR(VLOOKUP(C8,Sheet2!A:C,3,FALSE),""),VLOOKUP(C8,Sheet2!A:C,2,FALSE)),"") -> Dr. Hendy Briantoro | C8: 1571279780 | D8: accepted | E8: Preliminary FPGA-Based Fixed-Point Feature Extraction for Anomaly Detection in Multi-Sensor Mechatronic Actuator Signals | F8: I Nyoman Kusuma Wardana; Ida Bagus Irawan Purnama; I Gusti Ngurah Agung Dwijaya Saputra; I Wayan Marlon Managi; Padma Nyoman Crisnapati; Dechrit Maneetham | G8: 46247 | H8: 2026 Ninth International Conference on Vocational Education and Electrical Engineering (ICVEE) | I8: 17-18 September 2026 | J8: Surabaya, Indonesia | K8: Prof. Dr. Nurhayati, S.T., M.T. | L8: General Chair
A9: =IF(COUNTIF(Sheet2!A:A,C9)>0,"Ada","Tidak Ada") -> Ada | B9: =IF(A9="Ada",IF(IFERROR(VLOOKUP(C9,Sheet2!A:C,2,FALSE),"")="",IFERROR(VLOOKUP(C9,Sheet2!A:C,3,FALSE),""),VLOOKUP(C9,Sheet2!A:C,2,FALSE)),"") -> Lintang Deni Laksana | C9: 1571280074 | D9: accepted | E9: Design and Development of an Outseal PLC Mega-Based Trainer Kit as a Learning Tool for Electrical Motor Installation | F9: Mustofa Abi Hamid; Nuzulul Fikri; Irwanto; Muhammad Nurtanto; Bagus Dwi Cahyono; Muhammad Hakiki; Affero Ismail | G9: 46247 | H9: 2026 Ninth International Conference on Vocational Education and Electrical Engineering (ICVEE) | I9: 17-18 September 2026 | J9: Surabaya, Indonesia | K9: Prof. Dr. Nurhayati, S.T., M.T. | L9: General Chair
A10: =IF(COUNTIF(Sheet2!A:A,C10)>0,"Ada","Tidak Ada") -> Tidak Ada | B10: =IF(A10="Ada",IF(IFERROR(VLOOKUP(C10,Sheet2!A:C,2,FALSE),"")="",IFERROR(VLOOKUP(C10,Sheet2!A:C,3,FALSE),""),VLOOKUP(C10,Sheet2!A:C,2,FALSE)),"") | C10: 1571280332 | D10: accepted | E10: Comparative Analysis of GRU and LSTM for Microclimate Prediction in IoT-Enabled Smart Greenhouse | F10: Madukil Makruf; Mokh Sholihul Hadi; Ilham Ari Elbaith Zaeni; Masdukil Makruf | G10: 46247 | H10: 2026 Ninth International Conference on Vocational Education and Electrical Engineering (ICVEE) | I10: 17-18 September 2026 | J10: Surabaya, Indonesia | K10: Prof. Dr. Nurhayati, S.T., M.T. | L10: General Chair
A11: =IF(COUNTIF(Sheet2!A:A,C11)>0,"Ada","Tidak Ada") -> Ada | B11: =IF(A11="Ada",IF(IFERROR(VLOOKUP(C11,Sheet2!A:C,2,FALSE),"")="",IFERROR(VLOOKUP(C11,Sheet2!A:C,3,FALSE),""),VLOOKUP(C11,Sheet2!A:C,2,FALSE)),"") -> Mr. Fajar Romadhan | C11: 1571281021 | D11: accepted | E11: E-Laag: Design, Development, and Evaluation of an Intelligent Mobile Tourism Application for Ubiquitous Travel Support | F11: Randy O. Descarten; Angielee G. Camarin | G11: 46247 | H11: 2026 Ninth International Conference on Vocational Education and Electrical Engineering (ICVEE) | I11: 17-18 September 2026 | J11: Surabaya, Indonesia | K11: Prof. Dr. Nurhayati, S.T., M.T. | L11: General Chair
A12: =IF(COUNTIF(Sheet2!A:A,C12)>0,"Ada","Tidak Ada") -> Ada | B12: =IF(A12="Ada",IF(IFERROR(VLOOKUP(C12,Sheet2!A:C,2,FALSE),"")="",IFERROR(VLOOKUP(C12,Sheet2!A:C,3,FALSE),""),VLOOKUP(C12,Sheet2!A:C,2,FALSE)),"") -> Mrs. Alya Esa Mentari | C12: 1571281084 | D12: accepted | E12: Bagwis: A Co-Designed RPG-Based Ubiquitous Mobile Learning Application for Disaster Risk Reduction Education | F12: Jasten Keneth D Treceï¿½e | G12: 46247 | H12: 2026 Ninth International Conference on Vocational Education and Electrical Engineering (ICVEE) | I12: 17-18 September 2026 | J12: Surabaya, Indonesia | K12: Prof. Dr. Nurhayati, S.T., M.T. | L12: General Chair
A13: =IF(COUNTIF(Sheet2!A:A,C13)>0,"Ada","Tidak Ada") -> Ada | B13: =IF(A13="Ada",IF(IFERROR(VLOOKUP(C13,Sheet2!A:C,2,FALSE),"")="",IFERROR(VLOOKUP(C13,Sheet2!A:C,3,FALSE),""),VLOOKUP(C13,Sheet2!A:C,2,FALSE)),"") -> Nathanael Sitanggang; Putri Lynna A Luthan | C13: 1571282959 | D13: accepted | E13: Design and Evaluation of 923 MHz Inset-Fed Microstrip Antenna Arrays with 1x2 and 1x4 Configurations for LoRa Applications | F13: Afandi Sahputra; Syahrial; Teuku Yuliar Arif; Akhyar A; Yunida | G13: 46247 | H13: 2026 Ninth International Conference on Vocational Education and Electrical Engineering (ICVEE) | I13: 17-18 September 2026 | J13: Surabaya, Indonesia | K13: Prof. Dr. Nurhayati, S.T., M.T. | L13: General Chair
... A127: =IF(COUNTIF(Sheet2!A:A,C127)>0,"Ada","Tidak Ada") -> Tidak Ada | B127: =IF(A127="Ada",IF(IFERROR(VLOOKUP(C127,Sheet2!A:C,2,FALSE),"")="",IFERROR(VLOOKUP(C127,Sheet2!A:C,3,FALSE),""),VLOOKUP(C127,Sheet2!A:C,2,FALSE)),"") | C127: 1571310439 | D127: accepted | E127: Digital Knowledge Platform for Basic Electrical Systems | F127: Yulia Fransisca; Subuh Haryudo; Heri Suryaman; Hanif Rifai Adha | G127: 46247 | H127: 2026 Ninth International Conference on Vocational Education and Electrical Engineering (ICVEE) | I127: 17-18 September 2026 | J127: Surabaya, Indonesia | K127: Prof. Dr. Nurhayati, S.T., M.T. | L127: General Chair

Sheet Sheet2
A1: 1571267469 | C1: Dr. I Nyoman Kusuma Wardana
A2: 1571267484 | B2: Athif Fadheel Atharahman | C2: Athif Fadheel Atharahman
A3: 1571267967 | C3: Muhammad Andika Fadilla, S.Kom
A4: 1571268176 | B4: Muhammad Raya Maulana, S.T | C4: Muhammad Raya Maulana, S.T
A5: 1571279780 | C5: Dr. Hendy Briantoro
A6: 1571280074 | C6: Lintang Deni Laksana
A7: 1571281021 | C7: Mr. Fajar Romadhan
A8: 1571281084 | B8: Mrs. Alya Esa Mentari | C8: Mrs. Alya Esa Mentari
A9: 1571282959 | B9: Nathanael Sitanggang; Putri Lynna A Luthan | C9: Prof. Dr. Ir. Nathanael Sitanggang, S.T. M.Pd.
A10: 1571286979 | B10: Annisya Diaz Chandradewi, Dwi Dya Nindasari | C10: Annisya Diaz Chandradewi
A11: 1571289829 | B11: Kurnia Chairunnisa | C11: Ir. Erika Loniza, S.T., M.Eng
A12: 1571290388 | C12: Afandi Sahputra, S.T., M.T.
A13: 1571290818 | B13: Albertus Andika Tri Anggoro | C13: Albertus Andika Tri Anggoro
A14: 1571291272 | C14: Hamid Rahman, M.Kom.
A15: 1571291423 | B15: Putri Taqwa Prasetyaningrum | C15: Dr.Ir.Putri Taqwa Prasetyaningrum,S.T.,M.T
A16: 1571291625 | B16: Nanditya Vianti Putri | C16: Febri Liantoni, S.ST., M.Kom
A17: 1571291638 | C17: : Juris Vassa Ivandro, S.Kom
A18: 1571291668 | C18: Anisa Dzulkarnain, S.Kom., M.Kom.
A19: 1571291877 | C19: SUGITO, S.Kom
A20: 1571291935 | C20: rais nurwahyudin
A21: 1571292356 | B21: Prof. Nathanael Sitanggang; Prof. Putri Lynna A. Luthan | C21: Prof. Dr. Ir. Putri Lynna A. Luthan, M.Sc
A22: 1571292417 | C22: Sugeng Hari Wibowo
A23: 1571294926 | B23: Beny Prasetyo | C23: Beny Prasetyo, S.Kom., M.Kom
A24: 1571295713 | B24: Maskur | C24: Maskur, S.Kom., M.Kom
A25: 1571296305 | C25: Fauziyah Wafa'Abdillah, S.Tr.T.
A26: 1571297897 | B26: Putri Christianti Harefa | C26: Putri Christianti Harefa
A27: 1571298038 | B27: Stephanie Debora Assa | C27: Mochamad Nizar Palefi Ma'ady, S.Kom., M.Kom., M.IM
A28: 1571298045 | B28: Veldin A. Talorete Jr. | C28: Mr. Veldin A. Talorete Jr.
A29: 1571298209 | B29: Ramadhani Vanva Fauzia | C29: Mochamad Nizar Palefi Ma’ady, S.Kom., M.Kom., M.IM
A30: 1571298278 | B30: Mifta Nur Farid | C30: Mifta Nur Farid, S.T., M.T.
A31: 1571298458 | B31: Aditya Sheva Pratama | C31: Febri Liantoni
A32: 1571298558 | B32: Nurwahid Rahman | C32: Nurwahid Rahman
A33: 1571298976 | C33: Eric Julianto
A34: 1571300264 | B34: Mohammad Noer Dafiq | C34: Sritrusta Sukaridhoto ,ST., Ph.D.
A35: 1571300636 | C35: Eko Puji Laksono, S.Kom.,M.Kom
A36: 1571300706 | B36: DAVE SHANNA MARIE E. GIGAWIN & JOHN PAUL L. ULLEGUE | C36: DAVE SHANNA MARIE E. GIGAWIN
A37: 1571301191 | C37: Hastupara Amurwojakti
A38: 1571303126 | C38: Fadli Sirait, S.Si, M.T, Ph.D
A39: 1571304164 | B39: - | C39: Aditya Alpha Theodore, S.Pd.
A40: 1571304167 | B40: Chandra Restu Pradipto, Aloysius Bernanda Gunawan, Bambang Pratama | C40: Abdullah Billman
...
